Workbook

Sheet README
A1: MediLens — Kế hoạch sprint dài hạn 52 tuần / 26 sprint (VI/EN)
A2: Long-term sprint plan: 7 phase · 26 sprint × 10 ngày làm việc · 260 việc theo ngày · 14 cổng chất lượng
A4: Mục đích / Purpose
A5: File này chia toàn bộ dự án MediLens thành từng sprint và từng ngày làm việc. Mỗi ngày có một việc chính, role (mũ) đang đội, skill nên gọi cho agent, đầu ra và tiêu chí xong. This workbook breaks the project into sprints and working days; each day names the role, the agent skill to call, the deliverable and the definition of done.
A6: Tài liệu dự án đầy đủ (mục 22–29 giải thích vì sao có các việc này): https://claude.ai/code/artifact/364d9184-4a53-4093-bd32-f1a068f6ba92
A8: Cách dùng / How to use
A9: 1. Sheet Settings: nhập Ngày bắt đầu (ô vàng). Toàn bộ ngày trong Daily Plan, Sprints, Gates, Gantt tự tính lại bằng WORKDAY, bỏ qua cuối tuần và ngày trong sheet Holidays.
A10: 2. Sheet Daily Plan: mỗi ngày cập nhật Trạng thái (Chưa làm / Đang làm / Xong / Trễ / Bỏ), Giờ thực tế và Ghi chú — chỉ 3 cột này là ô nhập (nền vàng).
A11: 3. Sheet Dashboard: xem sprint hiện tại, việc hôm nay, cổng kế tiếp, % hoàn thành so với tiến độ kỳ vọng.
A12: 4. Cuối mỗi sprint (ngày 10): Review + Retro, cập nhật Sprints và Gates (Trạng thái cổng).
A13: 5. Muốn đổi kế hoạch gốc (baseline)? Ghi vào Change Log trước rồi mới sửa Daily Plan — giống quy trình Change Request ở dự án lớn.
A14: 6. Gọi agent: lấy tên trong cột Skill (ví dụ medilens-backend-engineer) để agent dùng đúng skill của role đó; với việc nhiều role, gọi medilens-orchestrator.
... A32: Tết 2027: CafeF — Bộ Nội vụ thông báo lịch nghỉ Tết Nguyên đán Đinh Mùi 2027 (cafef.vn). 24/11: FPT Shop tóm tắt Nghị quyết 28/2026/QH16. Giỗ Tổ 16/04/2027: officeholidays.com. Các ngày còn lại: Bộ luật Lao động 2019.

Sheet Dashboard
A1: MediLens — Tổng quan tiến độ / Progress dashboard
A2: Tự cập nhật từ Daily Plan, Sprints, Gates. Không cần nhập gì ở sheet này.
A3: Chỉ số | B3: Metric | C3: Giá trị / Value | E3: Phase | F3: Bắt đầu | G3: Kết thúc | H3: Số việc | I3: Xong | J3: % xong | K3: Giờ KH | L3: Giờ TT
A4: Ngày bắt đầu | B4: Start date | C4: =Settings!$C$4 -> 46314 | E4: =Roadmap!A4 -> P0 · Khởi tạo & Discovery | F4: =Roadmap!G4 -> 46314 | G4: =Roadmap!H4 -> 46339 | H4: =Roadmap!M4 -> 20 | I4: =Roadmap!N4 -> 0 | J4: =Roadmap!O4 -> 0 | K4: =Roadmap!P4 -> 80 | L4: =Roadmap!Q4 -> 0
A5: Ngày kết thúc dự kiến | B5: Planned end date | C5: =Settings!$C$11 -> 46692 | E5: =Roadmap!A5 -> P1 · Foundation | F5: =Roadmap!G5 -> 46342 | G5: =Roadmap!H5 -> 46384 | H5: =Roadmap!M5 -> 30 | I5: =Roadmap!N5 -> 0 | J5: =Roadmap!O5 -> 0 | K5: =Roadmap!P5 -> 120 | L5: =Roadmap!Q5 -> 0
A6: Hôm nay | B6: Today | C6: =TODAY() -> 46311 | E6: =Roadmap!A6 -> P2 · Build MVP | F6: =Roadmap!G6 -> 46385 | G6: =Roadmap!H6 -> 46476 | H6: =Roadmap!M6 -> 60 | I6: =Roadmap!N6 -> 0 | J6: =Roadmap!O6 -> 0 | K6: =Roadmap!P6 -> 240 | L6: =Roadmap!Q6 -> 0
A7: Sprint hiện tại | B7: Current sprint | C7: =IF(TODAY()<Settings!$C$4,"Chưa bắt đầu",IF(TODAY()>Settings!$C$11,"Đã kết thúc",INDEX('Daily Plan'!$C$4:$C$263,MATCH(TODAY(),'Daily Plan'!$B$4:$B$263,1)))) -> Chưa bắt đầu | E7: =Roadmap!A7 -> P3 · Hardening | F7: =Roadmap!G7 -> 46477 | G7: =Roadmap!H7 -> 46520 | H7: =Roadmap!M7 -> 30 | I7: =Roadmap!N7 -> 0 | J7: =Roadmap!O7 -> 0 | K7: =Roadmap!P7 -> 120 | L7: =Roadmap!Q7 -> 0
A8: Việc hôm nay | B8: Today's task | C8: =IFERROR(INDEX('Daily Plan'!$I$4:$I$263,MATCH(TODAY(),'Daily Plan'!$B$4:$B$263,0)),"Không có việc theo lịch hôm nay") -> Không có việc theo lịch hôm nay | E8: =Roadmap!A8 -> P4 · Beta & Launch v1.0 | F8: =Roadmap!G8 -> 46521 | G8: =Roadmap!H8 -> 46548 | H8: =Roadmap!M8 -> 20 | I8: =Roadmap!N8 -> 0 | J8: =Roadmap!O8 -> 0 | K8: =Roadmap!P8 -> 80 | L8: =Roadmap!Q8 -> 0
A9: Cổng kế tiếp | B9: Next gate | C9: =IF(_xlfn.MINIFS(Gates!$E$4:$E$17,Gates!$E$4:$E$17,">="&TODAY())=0,"—",INDEX(Gates!$A$4:$A$17,MATCH(_xlfn.MINIFS(Gates!$E$4:$E$17,Gates!$E$4:$E$17,">="&TODAY()),Gates!$E$4:$E$17,0))) -> G0 | E9: =Roadmap!A9 -> P5 · Hypercare & v1.5 | F9: =Roadmap!G9 -> 46549 | G9: =Roadmap!H9 -> 46604 | H9: =Roadmap!M9 -> 40 | I9: =Roadmap!N9 -> 0 | J9: =Roadmap!O9 -> 0 | K9: =Roadmap!P9 -> 160 | L9: =Roadmap!Q9 -> 0
A10: Ngày cổng kế tiếp | B10: Next gate date | C10: =IF(_xlfn.MINIFS(Gates!$E$4:$E$17,Gates!$E$4:$E$17,">="&TODAY())=0,"—",_xlfn.MINIFS(Gates!$E$4:$E$17,Gates!$E$4:$E$17,">="&TODAY())) -> 46339 | E10: =Roadmap!A10 -> P6 · v2.0 — CT & giải phẫu cá nhân | F10: =Roadmap!G10 -> 46605 | G10: =Roadmap!H10 -> 46692 | H10: =Roadmap!M10 -> 60 | I10: =Roadmap!N10 -> 0 | J10: =Roadmap!O10 -> 0 | K10: =Roadmap!P10 -> 240 | L10: =Roadmap!Q10 -> 0
A11: Tổng số việc | B11: Total tasks | C11: =COUNTA('Daily Plan'!$I$4:$I$263) -> 260
A12: Việc đã xong | B12: Tasks done | C12: =COUNTIF('Daily Plan'!$P$4:$P$263,"Xong") -> 0
A13: % hoàn thành | B13: % complete | C13: =IFERROR(C12/C11,0) -> 0 | E13: Cổng | F13: Sprint | G13: Ngày dự kiến | H13: Trạng thái
A14: Tiến độ kỳ vọng tới hôm nay | B14: Expected progress to date | C14: =IFERROR(COUNTIF('Daily Plan'!$B$4:$B$263,"<"&TODAY())/C11,0) -> 0 | E14: =Gates!A4 -> G0 | F14: =Gates!D4 -> S02 | G14: =Gates!E4 -> 46339 | H14: =Gates!J4 -> Chưa đến
A15: Chênh lệch (âm = chậm) | B15: Variance (negative = behind) | C15: =C13-C14 -> 0 | E15: =Gates!A5 -> G0-R | F15: =Gates!D5 -> S02 | G15: =Gates!E5 -> 46339 | H15: =Gates!J5 -> Chưa đến
A16: Việc quá hạn | B16: Overdue tasks | C16: =COUNTIF('Daily Plan'!$Q$4:$Q$263,"Quá hạn") -> 0 | E16: =Gates!A6 -> G1 | F16: =Gates!D6 -> S05 | G16: =Gates!E6 -> 46384 | H16: =Gates!J6 -> Chưa đến
A17: Giờ kế hoạch | B17: Planned hours | C17: =SUM('Daily Plan'!$N$4:$N$263) -> 1040 | E17: =Gates!A7 -> G1-D | F17: =Gates!D7 -> S05 | G17: =Gates!E7 -> 46384 | H17: =Gates!J7 -> Chưa đến
A18: Giờ thực tế | B18: Actual hours | C18: =SUM('Daily Plan'!$O$4:$O$263) -> 0 | E18: =Gates!A8 -> G2 | F18: =Gates!D8 -> S11 | G18: =Gates!E8 -> 46476 | H18: =Gates!J8 -> Chưa đến
E19: =Gates!A9 -> G2-CS | F19: =Gates!D9 -> S13 | G19: =Gates!E9 -> 46505 | H19: =Gates!J9 -> Chưa đến
E20: =Gates!A10 -> G3 | F20: =Gates!D10 -> S14 | G20: =Gates!E10 -> 46520 | H20: =Gates!J10 -> Chưa đến
A21: Trạng thái | B21: Status | C21: Số việc | E21: =Gates!A11 -> G3-P | F21: =Gates!D11 -> S14 | G21: =Gates!E11 -> 46520 | H21: =Gates!J11 -> Chưa đến
A22: Chưa làm | B22: Not started | C22: =COUNTIF('Daily Plan'!$P$4:$P$263,A22) -> 260 | E22: =Gates!A12 -> G4 | F22: =Gates!D12 -> S16 | G22: =Gates!E12 -> 46548 | H22: =Gates!J12 -> Chưa đến
A23: Đang làm | B23: In progress | C23: =COUNTIF('Daily Plan'!$P$4:$P$263,A23) -> 0 | E23: =Gates!A13 -> G5-H | F23: =Gates!D13 -> S18 | G23: =Gates!E13 -> 46576 | H23: =Gates!J13 -> Chưa đến
A24: Xong | B24: Done | C24: =COUNTIF('Daily Plan'!$P$4:$P$263,A24) -> 0 | E24: =Gates!A14 -> G5 | F24: =Gates!D14 -> S20 | G24: =Gates!E14 -> 46604 | H24: =Gates!J14 -> Chưa đến
A25: Trễ | B25: Late | C25: =COUNTIF('Daily Plan'!$P$4:$P$263,A25) -> 0 | E25: =Gates!A15 -> G0-R (CT) | F25: =Gates!D15 -> S21 | G25: =Gates!E15 -> 46618 | H25: =Gates!J15 -> Chưa đến
A26: Bỏ | B26: Dropped | C26: =COUNTIF('Daily Plan'!$P$4:$P$263,A26) -> 0 | E26: =Gates!A16 -> G1-D (lần 2) | F26: =Gates!D16 -> S22 | G26: =Gates!E16 -> 46636 | H26: =Gates!J16 -> Chưa đến
E27: =Gates!A17 -> G6 | F27: =Gates!D17 -> S26 | G27: =Gates!E17 -> 46692 | H27: =Gates!J17 -> Chưa đến

Sheet Settings
A1: Cài đặt / Settings
A2: Chỉ sửa ô nền vàng. Edit yellow cells only.
A3: Tham số | B3: Parameter | C3: Giá trị / Value | D3: Ghi chú / Note
A4: Ngày bắt đầu Sprint 1 | B4: Sprint 1 start date | C4: 46314 | D4: Nhập một ngày thứ Hai. Mặc định 19/10/2026 (thứ Hai sau ngày lập kế hoạch 16/10/2026).
A5: Số giờ mỗi ngày làm việc | B5: Hours per working day | C5: 4 | D5: 20 giờ/tuần part-time theo mục 1 của tài liệu (5 ngày × 4 giờ).
A6: Số ngày làm việc mỗi tuần | B6: Working days per week | C6: 5 | D6: Thứ Hai–Thứ Sáu; WORKDAY bỏ qua cuối tuần và ngày trong Holidays.
A7: Số giờ mỗi tuần | B7: Hours per week | C7: =C5*C6 -> 20 | D7: Tính từ 2 ô trên.
A8: Số ngày mỗi sprint | B8: Days per sprint | C8: 10 | D8: Sprint 2 tuần.
A9: Tổng số sprint | B9: Total sprints | C9: =COUNTA(Sprints!$A$4:$A$29) -> 26
A10: Tổng số ngày làm việc | B10: Total working days | C10: =COUNT('Daily Plan'!$A$4:$A$263) -> 260
A11: Ngày kết thúc dự kiến | B11: Planned end date | C11: =MAX('Daily Plan'!$B$4:$B$263) -> 46692 | D11: Thay đổi khi đổi ngày bắt đầu hoặc thêm ngày nghỉ.
A12: Tổng giờ kế hoạch | B12: Total planned hours | C12: =SUM('Daily Plan'!$N$4:$N$263) -> 1040

Sheet Roadmap
A1: Lộ trình 7 phase / Roadmap
A2: Thay cho lộ trình 32 tuần ở mục 5 của tài liệu: v1.0 vẫn ra mắt ở tuần 32, sau đó v1.5 (tuần 33–40) và v2.0 (tuần 41–52).
A3: Phase | B3: Tên (VI) | C3: Name (EN) | D3: Sprint từ | E3: Sprint đến | F3: Tuần KH | G3: Bắt đầu | H3: Kết thúc | I3: Mục tiêu (VI) | J3: Objective (EN) | K3: Cổng ra | L3: Phát hành | M3: Số việc | N3: Xong | O3: % xong | P3: Giờ KH | Q3: Giờ TT
A4: P0 · Khởi tạo & Discovery | B4: Khởi tạo & Discovery | C4: Initiation & Discovery | D4: S01 | E4: S02 | F4: 1–4 | G4: =INDEX(Sprints!$D$4:$D$29,MATCH(D4,Sprints!$A$4:$A$29,0)) -> 46314 | H4: =INDEX(Sprints!$E$4:$E$29,MATCH(E4,Sprints!$A$4:$A$29,0)) -> 46339 | I4: Charter, intended use, nghiên cứu người dùng, khóa phạm vi MVP, golden set v0, chọn OCR | J4: Charter, intended use, user research, MVP scope, golden set v0, OCR choice | K4: G0, G0-R | M4: =COUNTIF('Daily Plan'!$F$4:$F$263,A4) -> 20 | N4: =COUNTIFS('Daily Plan'!$F$4:$F$263,A4,'Daily Plan'!$P$4:$P$263,"Xong") -> 0 | O4: =IFERROR(N4/M4,0) -> 0 | P4: =SUMIFS('Daily Plan'!$N$4:$N$263,'Daily Plan'!$F$4:$F$263,A4) -> 80 | Q4: =SUMIFS('Daily Plan'!$O$4:$O$263,'Daily Plan'!$F$4:$F$263,A4) -> 0
A5: P1 · Foundation | B5: Foundation | C5: Foundation | D5: S03 | E5: S05 | F5: 5–10 | G5: =INDEX(Sprints!$D$4:$D$29,MATCH(D5,Sprints!$A$4:$A$29,0)) -> 46342 | H5: =INDEX(Sprints!$E$4:$E$29,MATCH(E5,Sprints!$A$4:$A$29,0)) -> 46384 | I5: Repo, CI/CD, landing zone AWS, data model, ranh giới PHI mức A, pipeline AI tối giản trên staging | J5: Repo, CI/CD, AWS landing zone, data model, level-A PHI boundary, minimal AI pipeline on staging | K5: G1, G1-D (lần 1) | M5: =COUNTIF('Daily Plan'!$F$4:$F$263,A5) -> 30 | N5: =COUNTIFS('Daily Plan'!$F$4:$F$263,A5,'Daily Plan'!$P$4:$P$263,"Xong") -> 0 | O5: =IFERROR(N5/M5,0) -> 0 | P5: =SUMIFS('Daily Plan'!$N$4:$N$263,'Daily Plan'!$F$4:$F$263,A5) -> 120 | Q5: =SUMIFS('Daily Plan'!$O$4:$O$263,'Daily Plan'!$F$4:$F$263,A5) -> 0
A6: P2 · Build MVP | B6: Build MVP | C6: Build MVP | D6: S06 | E6: S11 | F6: 11–22 | G6: =INDEX(Sprints!$D$4:$D$29,MATCH(D6,Sprints!$A$4:$A$29,0)) -> 46385 | H6: =INDEX(Sprints!$E$4:$E$29,MATCH(E6,Sprints!$A$4:$A$29,0)) -> 46476 | I6: Upload → OCR → trích xuất → review, viewer 2D/3D, 3 Unit, RAG có guardrail, timeline, chia sẻ, mô tả text | J6: Upload → OCR → extraction → review, 2D/3D viewer, 3 Units, guarded RAG, timeline, sharing, text input | K6: G2 | M6: =COUNTIF('Daily Plan'!$F$4:$F$263,A6) -> 60 | N6: =COUNTIFS('Daily Plan'!$F$4:$F$263,A6,'Daily Plan'!$P$4:$P$263,"Xong") -> 0 | O6: =IFERROR(N6/M6,0) -> 0 | P6: =SUMIFS('Daily Plan'!$N$4:$N$263,'Daily Plan'!$F$4:$F$263,A6) -> 240 | Q6: =SUMIFS('Daily Plan'!$O$4:$O$263,'Daily Plan'!$F$4:$F$263,A6) -> 0
A7: P3 · Hardening | B7: Hardening | C7: Hardening | D7: S12 | E7: S14 | F7: 23–28 | G7: =INDEX(Sprints!$D$4:$D$29,MATCH(D7,Sprints!$A$4:$A$29,0)) -> 46477 | H7: =INDEX(Sprints!$E$4:$E$29,MATCH(E7,Sprints!$A$4:$A$29,0)) -> 46520 | I7: Bảo mật mức B, hiệu năng, a11y, an toàn lâm sàng, pháp lý, pentest độc lập, prod sẵn sàng | J7: Level-B security, performance, a11y, clinical safety, regulatory, external pentest, prod ready | K7: G2-CS, G3, G3-P | M7: =COUNTIF('Daily Plan'!$F$4:$F$263,A7) -> 30 | N7: =COUNTIFS('Daily Plan'!$F$4:$F$263,A7,'Daily Plan'!$P$4:$P$263,"Xong") -> 0 | O7: =IFERROR(N7/M7,0) -> 0 | P7: =SUMIFS('Daily Plan'!$N$4:$N$263,'Daily Plan'!$F$4:$F$263,A7) -> 120 | Q7: =SUMIFS('Daily Plan'!$O$4:$O$263,'Daily Plan'!$F$4:$F$263,A7) -> 0
A8: P4 · Beta & Launch v1.0 | B8: Beta & Launch v1.0 | C8: Beta & Launch v1.0 | D8: S15 | E8: S16 | F8: 29–32 | G8: =INDEX(Sprints!$D$4:$D$29,MATCH(D8,Sprints!$A$4:$A$29,0)) -> 46521 | H8: =INDEX(Sprints!$E$4:$E$29,MATCH(E8,Sprints!$A$4:$A$29,0)) -> 46548 | I8: Beta kín 10–20 người, UAT, phát hành v1.0, bắt đầu hypercare | J8: Closed beta (10–20 users), UAT, v1.0 release, hypercare starts | K8: G4 | L8: v1.0 | M8: =COUNTIF('Daily Plan'!$F$4:$F$263,A8) -> 20 | N8: =COUNTIFS('Daily Plan'!$F$4:$F$263,A8,'Daily Plan'!$P$4:$P$263,"Xong") -> 0 | O8: =IFERROR(N8/M8,0) -> 0 | P8: =SUMIFS('Daily Plan'!$N$4:$N$263,'Daily Plan'!$F$4:$F$263,A8) -> 80 | Q8: =SUMIFS('Daily Plan'!$O$4:$O$263,'Daily Plan'!$F$4:$F$263,A8) -> 0
A9: P5 · Hypercare & v1.5 | B9: Hypercare & v1.5 | C9: Hypercare & v1.5 | D9: S17 | E9: S20 | F9: 33–40 | G9: =INDEX(Sprints!$D$4:$D$29,MATCH(D9,Sprints!$A$4:$A$29,0)) -> 46549 | H9: =INDEX(Sprints!$E$4:$E$29,MATCH(E9,Sprints!$A$4:$A$29,0)) -> 46604 | I9: Thoát hypercare, nhập bệnh án số (PDF/DOCX/FHIR), thư viện template giải phẫu, thêm 2 Unit, cascade đầy đủ, dữ liệu tầng 3–4 | J9: Exit hypercare, digital record import (PDF/DOCX/FHIR), anatomy template library, 2 more Units, full cascade, tier 3–4 data | K9: G5-H, G5 | L9: v1.5 | M9: =COUNTIF('Daily Plan'!$F$4:$F$263,A9) -> 40 | N9: =COUNTIFS('Daily Plan'!$F$4:$F$263,A9,'Daily Plan'!$P$4:$P$263,"Xong") -> 0 | O9: =IFERROR(N9/M9,0) -> 0 | P9: =SUMIFS('Daily Plan'!$N$4:$N$263,'Daily Plan'!$F$4:$F$263,A9) -> 160 | Q9: =SUMIFS('Daily Plan'!$O$4:$O$263,'Daily Plan'!$F$4:$F$263,A9) -> 0
A10: P6 · v2.0 — CT & giải phẫu cá nhân | B10: v2.0 — CT & giải phẫu cá nhân | C10: v2.0 — CT & patient-specific anatomy | D10: S21 | E10: S26 | F10: 41–52 | G10: =INDEX(Sprints!$D$4:$D$29,MATCH(D10,Sprints!$A$4:$A$29,0)) -> 46605 | H10: =INDEX(Sprints!$E$4:$E$29,MATCH(E10,Sprints!$A$4:$A$29,0)) -> 46692 | I10: Tái đánh giá pháp lý cho CT, DICOM an toàn, segmentation, mesh cá nhân, registration, distillation, FHIR export, đóng năm 1 | J10: Regulatory re-assessment for CT, safe DICOM, segmentation, patient mesh, registration, distillation, FHIR export, year-1 closure | K10: G0-R (CT), G1-D (lần 2), G6 | L10: v2.0 | M10: =COUNTIF('Daily Plan'!$F$4:$F$263,A10) -> 60 | N10: =COUNTIFS('Daily Plan'!$F$4:$F$263,A10,'Daily Plan'!$P$4:$P$263,"Xong") -> 0 | O10: =IFERROR(N10/M10,0) -> 0 | P10: =SUMIFS('Daily Plan'!$N$4:$N$263,'Daily Plan'!$F$4:$F$263,A10) -> 240 | Q10: =SUMIFS('Daily Plan'!$O$4:$O$263,'Daily Plan'!$F$4:$F$263,A10) -> 0
A11: Tổng / Total | M11: =SUM(M4:M10) -> 260 | N11: =SUM(N4:N10) -> 0 | O11: =IFERROR(N11/M11,0) -> 0 | P11: =SUM(P4:P10) -> 1040 | Q11: =SUM(Q4:Q10) -> 0

Sheet Gantt
A1: Gantt 52 tuần / 52-week Gantt
A2: Mỗi ô = 1 tuần kế hoạch (5 ngày làm việc). ◆ = tuần có cổng. Hàng 4: ngày bắt đầu tuần, tính từ Daily Plan.
A3: Sprint | B3: Phase | C3: 1 | D3: 2 | E3: 3 | F3: 4 | G3: 5 | H3: 6 | I3: 7 | J3: 8 | K3: 9 | L3: 10 | M3: 11 | N3: 12 | O3: 13 | P3: 14 | Q3: 15 | R3: 16 | S3: 17 | T3: 18 | U3: 19 | V3: 20 | W3: 21 | X3: 22 | Y3: 23 | Z3: 24 | AA3: 25 | AB3: 26 | AC3: 27 | AD3: 28 | AE3: 29 | AF3: 30 | AG3: 31 | AH3: 32 | AI3: 33 | AJ3: 34 | AK3: 35 | AL3: 36 | AM3: 37 | AN3: 38 | AO3: 39 | AP3: 40 | AQ3: 41 | AR3: 42 | AS3: 43 | AT3: 44 | AU3: 45 | AV3: 46 | AW3: 47 | AX3: 48 | AY3: 49 | AZ3: 50 | BA3: 51 | BB3: 52
A4: Bắt đầu tuần | C4: =INDEX('Daily Plan'!$B$4:$B$263,1) -> 46314 | D4: =INDEX('Daily Plan'!$B$4:$B$263,6) -> 46321 | E4: =INDEX('Daily Plan'!$B$4:$B$263,11) -> 46328 | F4: =INDEX('Daily Plan'!$B$4:$B$263,16) -> 46335 | G4: =INDEX('Daily Plan'!$B$4:$B$263,21) -> 46342 | H4: =INDEX('Daily Plan'!$B$4:$B$263,26) -> 46349 | I4: =INDEX('Daily Plan'!$B$4:$B$263,31) -> 46357 | J4: =INDEX('Daily Plan'!$B$4:$B$263,36) -> 46364 | K4: =INDEX('Daily Plan'!$B$4:$B$263,41) -> 46371 | L4: =INDEX('Daily Plan'!$B$4:$B$263,46) -> 46378 | M4: =INDEX('Daily Plan'!$B$4:$B$263,51) -> 46385 | N4: =INDEX('Daily Plan'!$B$4:$B$263,56) -> 46393 | O4: =INDEX('Daily Plan'!$B$4:$B$263,61) -> 46400 | P4: =INDEX('Daily Plan'!$B$4:$B$263,66) -> 46407 | Q4: =INDEX('Daily Plan'!$B$4:$B$263,71) -> 46414 | R4: =INDEX('Daily Plan'!$B$4:$B$263,76) -> 46421 | S4: =INDEX('Daily Plan'!$B$4:$B$263,81) -> 46435 | T4: =INDEX('Daily Plan'!$B$4:$B$263,86) -> 46442 | U4: =INDEX('Daily Plan'!$B$4:$B$263,91) -> 46449 | V4: =INDEX('Daily Plan'!$B$4:$B$263,96) -> 46456 | W4: =INDEX('Daily Plan'!$B$4:$B$263,101) -> 46463 | X4: =INDEX('Daily Plan'!$B$4:$B$263,106) -> 46470 | Y4: =INDEX('Daily Plan'!$B$4:$B$263,111) -> 46477 | Z4: =INDEX('Daily Plan'!$B$4:$B$263,116) -> 46484 | AA4: =INDEX('Daily Plan'!$B$4:$B$263,121) -> 46491 | AB4: =INDEX('Daily Plan'!$B$4:$B$263,126) -> 46499 | AC4: =INDEX('Daily Plan'!$B$4:$B$263,131) -> 46506 | AD4: =INDEX('Daily Plan'!$B$4:$B$263,136) -> 46514 | AE4: =INDEX('Daily Plan'!$B$4:$B$263,141) -> 46521 | AF4: =INDEX('Daily Plan'!$B$4:$B$263,146) -> 46528 | AG4: =INDEX('Daily Plan'!$B$4:$B$263,151) -> 46535 | AH4: =INDEX('Daily Plan'!$B$4:$B$263,156) -> 46542 | AI4: =INDEX('Daily Plan'!$B$4:$B$263,161) -> 46549 | AJ4: =INDEX('Daily Plan'!$B$4:$B$263,166) -> 46556 | AK4: =INDEX('Daily Plan'!$B$4:$B$263,171) -> 46563 | AL4: =INDEX('Daily Plan'!$B$4:$B$263,176) -> 46570 | AM4: =INDEX('Daily Plan'!$B$4:$B$263,181) -> 46577 | AN4: =INDEX('Daily Plan'!$B$4:$B$263,186) -> 46584 | AO4: =INDEX('Daily Plan'!$B$4:$B$263,191) -> 46591 | AP4: =INDEX('Daily Plan'!$B$4:$B$263,196) -> 46598 | AQ4: =INDEX('Daily Plan'!$B$4:$B$263,201) -> 46605 | AR4: =INDEX('Daily Plan'!$B$4:$B$263,206) -> 46612 | AS4: =INDEX('Daily Plan'!$B$4:$B$263,211) -> 46619 | AT4: =INDEX('Daily Plan'!$B$4:$B$263,216) -> 46626 | AU4: =INDEX('Daily Plan'!$B$4:$B$263,221) -> 46637 | AV4: =INDEX('Daily Plan'!$B$4:$B$263,226) -> 46644 | AW4: =INDEX('Daily Plan'!$B$4:$B$263,231) -> 46651 | AX4: =INDEX('Daily Plan'!$B$4:$B$263,236) -> 46658 | AY4: =INDEX('Daily Plan'!$B$4:$B$263,241) -> 46665 | AZ4: =INDEX('Daily Plan'!$B$4:$B$263,246) -> 46672 | BA4: =INDEX('Daily Plan'!$B$4:$B$263,251) -> 46679 | BB4: =INDEX('Daily Plan'!$B$4:$B$263,256) -> 46686
A5: S01 | B5: P0 · Khởi tạo & Discovery
A6: S02 | B6: P0 · Khởi tạo & Discovery | F6: ◆
A7: S03 | B7: P1 · Foundation
A8: S04 | B8: P1 · Foundation
A9: S05 | B9: P1 · Foundation | L9: ◆
A10: S06 | B10: P2 · Build MVP
A11: S07 | B11: P2 · Build MVP
A12: S08 | B12: P2 · Build MVP
A13: S09 | B13: P2 · Build MVP
A14: S10 | B14: P2 · Build MVP
A15: S11 | B15: P2 · Build MVP | X15: ◆
A16: S12 | B16: P3 · Hardening
A17: S13 | B17: P3 · Hardening | AB17: ◆
A18: S14 | B18: P3 · Hardening | AD18: ◆
A19: S15 | B19: P4 · Beta & Launch v1.0
A20: S16 | B20: P4 · Beta & Launch v1.0 | AH20: ◆
A21: S17 | B21: P5 · Hypercare & v1.5
A22: S18 | B22: P5 · Hypercare & v1.5 | AL22: ◆
A23: S19 | B23: P5 · Hypercare & v1.5
A24: S20 | B24: P5 · Hypercare & v1.5 | AP24: ◆
A25: S21 | B25: P6 · v2.0 — CT & giải phẫu cá nhân | AR25: ◆
A26: S22 | B26: P6 · v2.0 — CT & giải phẫu cá nhân | AT26: ◆
A27: S23 | B27: P6 · v2.0 — CT & giải phẫu cá nhân
A28: S24 | B28: P6 · v2.0 — CT & giải phẫu cá nhân
A29: S25 | B29: P6 · v2.0 — CT & giải phẫu cá nhân
A30: S26 | B30: P6 · v2.0 — CT & giải phẫu cá nhân | BB30: ◆
A32: Chú giải màu phase:
B33: P0 · Khởi tạo & Discovery / Initiation & Discovery
B34: P1 · Foundation / Foundation
B35: P2 · Build MVP / Build MVP
B36: P3 · Hardening / Hardening
B37: P4 · Beta & Launch v1.0 / Beta & Launch v1.0
B38: P5 · Hypercare & v1.5 / Hypercare & v1.5
B39: P6 · v2.0 — CT & giải phẫu cá nhân / v2.0 — CT & patient-specific anatomy

Sheet Sprints
A1: 26 sprint / Sprint overview
A2: Ngày bắt đầu/kết thúc, giờ và % xong tự tính từ Daily Plan.
A3: Sprint | B3: Phase | C3: Tuần KH | D3: Bắt đầu | E3: Kết thúc | F3: Mục tiêu sprint (VI) | G3: Sprint goal (EN) | H3: Demo cuối sprint | I3: Cổng | J3: Role trong sprint (kế hoạch gốc) | K3: Rủi ro trọng tâm | L3: Giờ KH | M3: Giờ TT | N3: Việc xong | O3: % xong
A4: S01 | B4: P0 · Khởi tạo & Discovery | C4: 1–2 | D4: =INDEX('Daily Plan'!$B$4:$B$263,MATCH(A4,'Daily Plan'!$C$4:$C$263,0)) -> 46314 | E4: =INDEX('Daily Plan'!$B$4:$B$263,MATCH(A4,'Daily Plan'!$C$4:$C$263,0)+9) -> 46325 | F4: Khởi tạo dự án: charter, intended use, nghiên cứu người dùng | G4: Initiate the project: charter, intended use, user research | H4: Charter + Intended Use + tổng hợp 5 cuộc phỏng vấn | J4: PM, REG, BA, UX, CSO | K4: Bỏ qua khởi tạo vì muốn code ngay | L4: =SUMIFS('Daily Plan'!$N$4:$N$263,'Daily Plan'!$C$4:$C$263,A4) -> 40 | M4: =SUMIFS('Daily Plan'!$O$4:$O$263,'Daily Plan'!$C$4:$C$263,A4) -> 0 | N4: =COUNTIFS('Daily Plan'!$C$4:$C$263,A4,'Daily Plan'!$P$4:$P$263,"Xong") -> 0 | O4: =IFERROR(N4/COUNTIF('Daily Plan'!$C$4:$C$263,A4),0) -> 0
A5: S02 | B5: P0 · Khởi tạo & Discovery | C5: 3–4 | D5: =INDEX('Daily Plan'!$B$4:$B$263,MATCH(A5,'Daily Plan'!$C$4:$C$263,0)) -> 46328 | E5: =INDEX('Daily Plan'!$B$4:$B$263,MATCH(A5,'Daily Plan'!$C$4:$C$263,0)+9) -> 46339 | F5: Khóa phạm vi MVP, BRD, prototype, golden set v0, chọn OCR → G0, G0-R | G5: Lock MVP scope, BRD, prototype, golden set v0, OCR choice → G0, G0-R | H5: Prototype click-through + báo cáo bake-off OCR | I5: G0, G0-R | J5: BA, UX, AI, DC, SA, REG, QC | K5: Scope creep: muốn làm mọi Khoa cùng lúc | L5: =SUMIFS('Daily Plan'!$N$4:$N$263,'Daily Plan'!$C$4:$C$263,A5) -> 40 | M5: =SUMIFS('Daily Plan'!$O$4:$O$263,'Daily Plan'!$C$4:$C$263,A5) -> 0 | N5: =COUNTIFS('Daily Plan'!$C$4:$C$263,A5,'Daily Plan'!$P$4:$P$263,"Xong") -> 0 | O5: =IFERROR(N5/COUNTIF('Daily Plan'!$C$4:$C$263,A5),0) -> 0
A6: S03 | B6: P1 · Foundation | C6: 5–6 | D6: =INDEX('Daily Plan'!$B$4:$B$263,MATCH(A6,'Daily Plan'!$C$4:$C$263,0)) -> 46342 | E6: =INDEX('Daily Plan'!$B$4:$B$263,MATCH(A6,'Daily Plan'!$C$4:$C$263,0)+9) -> 46356 | F6: Nền móng kỹ thuật: repo, CI, landing zone AWS, VPC Terraform, khung auth | G6: Engineering foundation: repo, CI, AWS landing zone, Terraform VPC, auth skeleton | H6: Đăng nhập → trang trống trên môi trường nonprod | J6: SA, OPS, BE, FE, SEC, PM | K6: Sa đà hạ tầng > 25% thời gian sprint | L6: =SUMIFS('Daily Plan'!$N$4:$N$263,'Daily Plan'!$C$4:$C$263,A6) -> 40 | M6: =SUMIFS('Daily Plan'!$O$4:$O$263,'Daily Plan'!$C$4:$C$263,A6) -> 0 | N6: =COUNTIFS('Daily Plan'!$C$4:$C$263,A6,'Daily Plan'!$P$4:$P$263,"Xong") -> 0 | O6: =IFERROR(N6/COUNTIF('Daily Plan'!$C$4:$C$263,A6),0) -> 0
A7: S04 | B7: P1 · Foundation | C7: 7–8 | D7: =INDEX('Daily Plan'!$B$4:$B$263,MATCH(A7,'Daily Plan'!$C$4:$C$263,0)) -> 46357 | E7: =INDEX('Daily Plan'!$B$4:$B$263,MATCH(A7,'Daily Plan'!$C$4:$C$263,0)+9) -> 46370 | F7: Data model, ranh giới PHI mức A, upload an toàn, design system | G7: Data model, level-A PHI boundary, secure upload, design system | H7: Upload ảnh vào bucket quarantine; file độc bị chặn | J7: BE, OPS, UX, FE, DE, QA | K7: Lộ PHI do thiết kế schema sai | L7: =SUMIFS('Daily Plan'!$N$4:$N$263,'Daily Plan'!$C$4:$C$263,A7) -> 40 | M7: =SUMIFS('Daily Plan'!$O$4:$O$263,'Daily Plan'!$C$4:$C$263,A7) -> 0 | N7: =COUNTIFS('Daily Plan'!$C$4:$C$263,A7,'Daily Plan'!$P$4:$P$263,"Xong") -> 0 | O7: =IFERROR(N7/COUNTIF('Daily Plan'!$C$4:$C$263,A7),0) -> 0
A8: S05 | B8: P1 · Foundation | C8: 9–10 | D8: =INDEX('Daily Plan'!$B$4:$B$263,MATCH(A8,'Daily Plan'!$C$4:$C$263,0)) -> 46371 | E8: =INDEX('Daily Plan'!$B$4:$B$263,MATCH(A8,'Daily Plan'!$C$4:$C$263,0)+9) -> 46384 | F8: Pipeline AI tối giản end-to-end trên staging; AI Gateway v0 → G1, G1-D (dữ liệu đánh giá) | G8: Minimal end-to-end AI pipeline on staging; AI Gateway v0 → G1, G1-D (evaluation data) | H8: 1 ảnh bệnh án → JSON có trích dẫn trên staging | I8: G1-D, G1 | J8: AI, MLO, OPS, CIN, DC, QC | K8: LLM bịa thông tin; chi phí token tăng | L8: =SUMIFS('Daily Plan'!$N$4:$N$263,'Daily Plan'!$C$4:$C$263,A8) -> 40 | M8: =SUMIFS('Daily Plan'!$O$4:$O$263,'Daily Plan'!$C$4:$C$263,A8) -> 0 | N8: =COUNTIFS('Daily Plan'!$C$4:$C$263,A8,'Daily Plan'!$P$4:$P$263,"Xong") -> 0 | O8: =IFERROR(N8/COUNTIF('Daily Plan'!$C$4:$C$263,A8),0) -> 0
A9: S06 | B9: P2 · Build MVP | C9: 11–12 | D9: =INDEX('Daily Plan'!$B$4:$B$263,MATCH(A9,'Daily Plan'!$C$4:$C$263,0)) -> 46385 | E9: =INDEX('Daily Plan'!$B$4:$B$263,MATCH(A9,'Daily Plan'!$C$4:$C$263,0)+9) -> 46399 | F9: Upload an toàn + state machine + OCR, trạng thái realtime | G9: Secure upload + state machine + OCR with realtime status | H9: Upload ảnh, thấy text OCR và trạng thái realtime | J9: BA, FE, BE, AI, QA, SEC, TW, PM | K9: OCR kém với ảnh điện thoại | L9: =SUMIFS('Daily Plan'!$N$4:$N$263,'Daily Plan'!$C$4:$C$263,A9) -> 40 | M9: =SUMIFS('Daily Plan'!$O$4:$O$263,'Daily Plan'!$C$4:$C$263,A9) -> 0 | N9: =COUNTIFS('Daily Plan'!$C$4:$C$263,A9,'Daily Plan'!$P$4:$P$263,"Xong") -> 0 | O9: =IFERROR(N9/COUNTIF('Daily Plan'!$C$4:$C$263,A9),0) -> 0
A10: S07 | B10: P2 · Build MVP | C10: 13–14 | D10: =INDEX('Daily Plan'!$B$4:$B$263,MATCH(A10,'Daily Plan'!$C$4:$C$263,0)) -> 46400 | E10: =INDEX('Daily Plan'!$B$4:$B$263,MATCH(A10,'Daily Plan'!$C$4:$C$263,0)+9) -> 46413 | F10: Trích xuất LLM + màn Review + cascade model v1 | G10: LLM extraction + Review screen + model cascade v1 | H10: Sửa và xác nhận kết quả, highlight bounding box | J10: AI, BE, FE, MLO, QA, CSO, DE, PM | K10: Hallucination; người dùng tin AI tuyệt đối | L10: =SUMIFS('Daily Plan'!$N$4:$N$263,'Daily Plan'!$C$4:$C$263,A10) -> 40 | M10: =SUMIFS('Daily Plan'!$O$4:$O$263,'Daily Plan'!$C$4:$C$263,A10) -> 0 | N10: =COUNTIFS('Daily Plan'!$C$4:$C$263,A10,'Daily Plan'!$P$4:$P$263,"Xong") -> 0 | O10: =IFERROR(N10/COUNTIF('Daily Plan'!$C$4:$C$263,A10),0) -> 0
A11: S08 | B11: P2 · Build MVP | C11: 15–16 | D11: =INDEX('Daily Plan'!$B$4:$B$263,MATCH(A11,'Daily Plan'!$C$4:$C$263,0)) -> 46414 | E11: =INDEX('Daily Plan'!$B$4:$B$263,MATCH(A11,'Daily Plan'!$C$4:$C$263,0)+9) -> 46434 | F11: Viewer 2D toàn thân + Unit Răng hàm mặt | G11: 2D whole-body viewer + Dental Unit | H11: Sơ đồ răng FDI tô màu theo bệnh án | J11: UX, ART, FE, BE, AI, CIN, QA, CSO, PM | K11: Sai số răng/bên | L11: =SUMIFS('Daily Plan'!$N$4:$N$263,'Daily Plan'!$C$4:$C$263,A11) -> 40 | M11: =SUMIFS('Daily Plan'!$O$4:$O$263,'Daily Plan'!$C$4:$C$263,A11) -> 0 | N11: =COUNTIFS('Daily Plan'!$C$4:$C$263,A11,'Daily Plan'!$P$4:$P$263,"Xong") -> 0 | O11: =IFERROR(N11/COUNTIF('Daily Plan'!$C$4:$C$263,A11),0) -> 0
A12: S09 | B12: P2 · Build MVP | C12: 17–18 | D12: =INDEX('Daily Plan'!$B$4:$B$263,MATCH(A12,'Daily Plan'!$C$4:$C$263,0)) -> 46435 | E12: =INDEX('Daily Plan'!$B$4:$B$263,MATCH(A12,'Daily Plan'!$C$4:$C$263,0)+9) -> 46448 | F12: Viewer 3D + Unit Tim mạch | G12: 3D viewer + Cardiology Unit | H12: Xoay/zoom mô hình, bấm vùng xem chi tiết | J12: FE, ART, BE, AI, UX, QA, SEC, PM | K12: 3D giật trên máy yếu | L12: =SUMIFS('Daily Plan'!$N$4:$N$263,'Daily Plan'!$C$4:$C$263,A12) -> 40 | M12: =SUMIFS('Daily Plan'!$O$4:$O$263,'Daily Plan'!$C$4:$C$263,A12) -> 0 | N12: =COUNTIFS('Daily Plan'!$C$4:$C$263,A12,'Daily Plan'!$P$4:$P$263,"Xong") -> 0 | O12: =IFERROR(N12/COUNTIF('Daily Plan'!$C$4:$C$263,A12),0) -> 0
A13: S10 | B13: P2 · Build MVP | C13: 19–20 | D13: =INDEX('Daily Plan'!$B$4:$B$263,MATCH(A13,'Daily Plan'!$C$4:$C$263,0)) -> 46449 | E13: =INDEX('Daily Plan'!$B$4:$B$263,MATCH(A13,'Daily Plan'!$C$4:$C$263,0)+9) -> 46462 | F13: Unit Ung bướu + giải thích RAG có guardrail | G13: Oncology Unit + guarded RAG explanations | H13: Khối u, hạch, di căn; hỏi đáp có trích dẫn | J13: BA, AI, FE, TW, MLO, QA, CSO, PM | K13: Hình ảnh ung thư gây sợ; trả lời vượt phạm vi | L13: =SUMIFS('Daily Plan'!$N$4:$N$263,'Daily Plan'!$C$4:$C$263,A13) -> 40 | M13: =SUMIFS('Daily Plan'!$O$4:$O$263,'Daily Plan'!$C$4:$C$263,A13) -> 0 | N13: =COUNTIFS('Daily Plan'!$C$4:$C$263,A13,'Daily Plan'!$P$4:$P$263,"Xong") -> 0 | O13: =IFERROR(N13/COUNTIF('Daily Plan'!$C$4:$C$263,A13),0) -> 0
A14: S11 | B14: P2 · Build MVP | C14: 21–22 | D14: =INDEX('Daily Plan'!$B$4:$B$263,MATCH(A14,'Daily Plan'!$C$4:$C$263,0)) -> 46463 | E14: =INDEX('Daily Plan'!$B$4:$B$263,MATCH(A14,'Daily Plan'!$C$4:$C$263,0)+9) -> 46476 | F14: Timeline pre/post, mô tả bằng text, chia sẻ, admin, quyền dữ liệu → G2 | G14: Pre/post timeline, text descriptions, sharing, admin, data rights → G2 | H14: So sánh hai lần khám, chia sẻ có hạn cho bác sĩ | I14: G2 | J14: FE, BE, QA, AI, TW, QC | K14: Lỗi phân quyền khi chia sẻ | L14: =SUMIFS('Daily Plan'!$N$4:$N$263,'Daily Plan'!$C$4:$C$263,A14) -> 40 | M14: =SUMIFS('Daily Plan'!$O$4:$O$263,'Daily Plan'!$C$4:$C$263,A14) -> 0 | N14: =COUNTIFS('Daily Plan'!$C$4:$C$263,A14,'Daily Plan'!$P$4:$P$263,"Xong") -> 0 | O14: =IFERROR(N14/COUNTIF('Daily Plan'!$C$4:$C$263,A14),0) -> 0
A15: S12 | B15: P3 · Hardening | C15: 23–24 | D15: =INDEX('Daily Plan'!$B$4:$B$263,MATCH(A15,'Daily Plan'!$C$4:$C$263,0)) -> 46477 | E15: =INDEX('Daily Plan'!$B$4:$B$263,MATCH(A15,'Daily Plan'!$C$4:$C$263,0)+9) -> 46490 | F15: Bảo mật mức B, hiệu năng, khả năng truy cập | G15: Level-B security, performance, accessibility | H15: Báo cáo load test + DAST sạch + kiến trúc mức B | J15: SEC, OPS, BE, QA, FE, SRE, PM | K15: Phát hiện lỗ hổng muộn | L15: =SUMIFS('Daily Plan'!$N$4:$N$263,'Daily Plan'!$C$4:$C$263,A15) -> 40 | M15: =SUMIFS('Daily Plan'!$O$4:$O$263,'Daily Plan'!$C$4:$C$263,A15) -> 0 | N15: =COUNTIFS('Daily Plan'!$C$4:$C$263,A15,'Daily Plan'!$P$4:$P$263,"Xong") -> 0 | O15: =IFERROR(N15/COUNTIF('Daily Plan'!$C$4:$C$263,A15),0) -> 0
A16: S13 | B16: P3 · Hardening | C16: 25–26 | D16: =INDEX('Daily Plan'!$B$4:$B$263,MATCH(A16,'Daily Plan'!$C$4:$C$263,0)) -> 46491 | E16: =INDEX('Daily Plan'!$B$4:$B$263,MATCH(A16,'Daily Plan'!$C$4:$C$263,0)+9) -> 46505 | F16: An toàn lâm sàng, pháp lý, usability tổng kết → G2-CS | G16: Clinical safety, regulatory, summative usability → G2-CS | H16: Clinical Safety Case + kết quả xác thực bởi bác sĩ | I16: G2-CS | J16: CSO, UX, REG, SEC, SRE, QC | K16: Không có bác sĩ thật ký duyệt | L16: =SUMIFS('Daily Plan'!$N$4:$N$263,'Daily Plan'!$C$4:$C$263,A16) -> 40 | M16: =SUMIFS('Daily Plan'!$O$4:$O$263,'Daily Plan'!$C$4:$C$263,A16) -> 0 | N16: =COUNTIFS('Daily Plan'!$C$4:$C$263,A16,'Daily Plan'!$P$4:$P$263,"Xong") -> 0 | O16: =IFERROR(N16/COUNTIF('Daily Plan'!$C$4:$C$263,A16),0) -> 0
A17: S14 | B17: P3 · Hardening | C17: 27–28 | D17: =INDEX('Daily Plan'!$B$4:$B$263,MATCH(A17,'Daily Plan'!$C$4:$C$263,0)) -> 46506 | E17: =INDEX('Daily Plan'!$B$4:$B$263,MATCH(A17,'Daily Plan'!$C$4:$C$263,0)+9) -> 46520 | F17: Pentest độc lập, UAT, prod sẵn sàng → G3, G3-P | G17: Independent pentest, UAT, production ready → G3, G3-P | H17: Readiness report GO + prod rollback test | I17: G3, G3-P | J17: SEC, BE, AI, QA, TW, SUP, OPS, QC | K17: Finding High phải sửa gấp làm trễ launch | L17: =SUMIFS('Daily Plan'!$N$4:$N$263,'Daily Plan'!$C$4:$C$263,A17) -> 40 | M17: =SUMIFS('Daily Plan'!$O$4:$O$263,'Daily Plan'!$C$4:$C$263,A17) -> 0 | N17: =COUNTIFS('Daily Plan'!$C$4:$C$263,A17,'Daily Plan'!$P$4:$P$263,"Xong") -> 0 | O17: =IFERROR(N17/COUNTIF('Daily Plan'!$C$4:$C$263,A17),0) -> 0
A18: S15 | B18: P4 · Beta & Launch v1.0 | C18: 29–30 | D18: =INDEX('Daily Plan'!$B$4:$B$263,MATCH(A18,'Daily Plan'!$C$4:$C$263,0)) -> 46521 | E18: =INDEX('Daily Plan'!$B$4:$B$263,MATCH(A18,'Daily Plan'!$C$4:$C$263,0)+9) -> 46534 | F18: Beta kín 10–20 người | G18: Closed beta with 10–20 users | H18: Báo cáo beta tuần 1–2 | J18: PM, OPS, SUP, SRE, BA, BE, AI, CSO, DE | K18: Người beta dùng dữ liệu thật trước khi sẵn sàng | L18: =SUMIFS('Daily Plan'!$N$4:$N$263,'Daily Plan'!$C$4:$C$263,A18) -> 40 | M18: =SUMIFS('Daily Plan'!$O$4:$O$263,'Daily Plan'!$C$4:$C$263,A18) -> 0 | N18: =COUNTIFS('Daily Plan'!$C$4:$C$263,A18,'Daily Plan'!$P$4:$P$263,"Xong") -> 0 | O18: =IFERROR(N18/COUNTIF('Daily Plan'!$C$4:$C$263,A18),0) -> 0
A19: S16 | B19: P4 · Beta & Launch v1.0 | C19: 31–32 | D19: =INDEX('Daily Plan'!$B$4:$B$263,MATCH(A19,'Daily Plan'!$C$4:$C$263,0)) -> 46535 | E19: =INDEX('Daily Plan'!$B$4:$B$263,MATCH(A19,'Daily Plan'!$C$4:$C$263,0)+9) -> 46548 | F19: Phát hành v1.0 → G4 | G19: Release v1.0 → G4 | H19: v1.0 chạy trên prod + báo cáo tuần đầu | I19: G4 | J19: PM, QA, TW, QC, OPS, SRE, SUP, FE, DE | K19: Sự cố ngày đầu ra mắt | L19: =SUMIFS('Daily Plan'!$N$4:$N$263,'Daily Plan'!$C$4:$C$263,A19) -> 40 | M19: =SUMIFS('Daily Plan'!$O$4:$O$263,'Daily Plan'!$C$4:$C$263,A19) -> 0 | N19: =COUNTIFS('Daily Plan'!$C$4:$C$263,A19,'Daily Plan'!$P$4:$P$263,"Xong") -> 0 | O19: =IFERROR(N19/COUNTIF('Daily Plan'!$C$4:$C$263,A19),0) -> 0
A20: S17 | B20: P5 · Hypercare & v1.5 | C20: 33–34 | D20: =INDEX('Daily Plan'!$B$4:$B$263,MATCH(A20,'Daily Plan'!$C$4:$C$263,0)) -> 46549 | E20: =INDEX('Daily Plan'!$B$4:$B$263,MATCH(A20,'Daily Plan'!$C$4:$C$263,0)+9) -> 46562 | F20: Hypercare + nhập bệnh án số (PDF có lớp chữ, DOCX, FHIR) | G20: Hypercare + digital record import (text-layer PDF, DOCX, FHIR) | H20: Nhập PDF/FHIR → finding không qua OCR/LLM | J20: PM, BE, CIN, QA, AI, MLO, SUP, SRE | K20: File nhập độc hại; FHIR không chuẩn | L20: =SUMIFS('Daily Plan'!$N$4:$N$263,'Daily Plan'!$C$4:$C$263,A20) -> 40 | M20: =SUMIFS('Daily Plan'!$O$4:$O$263,'Daily Plan'!$C$4:$C$263,A20) -> 0 | N20: =COUNTIFS('Daily Plan'!$C$4:$C$263,A20,'Daily Plan'!$P$4:$P$263,"Xong") -> 0 | O20: =IFERROR(N20/COUNTIF('Daily Plan'!$C$4:$C$263,A20),0) -> 0
A21: S18 | B21: P5 · Hypercare & v1.5 | C21: 35–36 | D21: =INDEX('Daily Plan'!$B$4:$B$263,MATCH(A21,'Daily Plan'!$C$4:$C$263,0)) -> 46563 | E21: =INDEX('Daily Plan'!$B$4:$B$263,MATCH(A21,'Daily Plan'!$C$4:$C$263,0)+9) -> 46576 | F21: Thư viện template giải phẫu + data donation opt-in → G5-H | G21: Anatomy template library + opt-in data donation → G5-H | H21: Template theo giới/tuổi, ẩn cơ quan đã cắt, biểu tượng implant | I21: G5-H | J21: UX, ART, FE, BE, REG, DC, QA, CSO, SUP, QC | K21: Hiển thị sai giải phẫu đặc biệt | L21: =SUMIFS('Daily Plan'!$N$4:$N$263,'Daily Plan'!$C$4:$C$263,A21) -> 40 | M21: =SUMIFS('Daily Plan'!$O$4:$O$263,'Daily Plan'!$C$4:$C$263,A21) -> 0 | N21: =COUNTIFS('Daily Plan'!$C$4:$C$263,A21,'Daily Plan'!$P$4:$P$263,"Xong") -> 0 | O21: =IFERROR(N21/COUNTIF('Daily Plan'!$C$4:$C$263,A21),0) -> 0
A22: S19 | B22: P5 · Hypercare & v1.5 | C22: 37–38 | D22: =INDEX('Daily Plan'!$B$4:$B$263,MATCH(A22,'Daily Plan'!$C$4:$C$263,0)) -> 46577 | E22: =INDEX('Daily Plan'!$B$4:$B$263,MATCH(A22,'Daily Plan'!$C$4:$C$263,0)+9) -> 46590 | F22: Thêm Unit Hô hấp, Thận–Tiết niệu + cascade model đầy đủ | G22: Add Respiratory and Nephrology–Urology Units + full model cascade | H22: 2 Unit mới + dashboard chi phí theo tầng | J22: BA, ART, BE, AI, MLO, FE, CIN, QA, PM | K22: Chi phí tăng khi thêm Unit | L22: =SUMIFS('Daily Plan'!$N$4:$N$263,'Daily Plan'!$C$4:$C$263,A22) -> 40 | M22: =SUMIFS('Daily Plan'!$O$4:$O$263,'Daily Plan'!$C$4:$C$263,A22) -> 0 | N22: =COUNTIFS('Daily Plan'!$C$4:$C$263,A22,'Daily Plan'!$P$4:$P$263,"Xong") -> 0 | O22: =IFERROR(N22/COUNTIF('Daily Plan'!$C$4:$C$263,A22),0) -> 0
A23: S20 | B23: P5 · Hypercare & v1.5 | C23: 39–40 | D23: =INDEX('Daily Plan'!$B$4:$B$263,MATCH(A23,'Daily Plan'!$C$4:$C$263,0)) -> 46591 | E23: =INDEX('Daily Plan'!$B$4:$B$263,MATCH(A23,'Daily Plan'!$C$4:$C$263,0)+9) -> 46604 | F23: Hợp tác dữ liệu, gán nhãn, phát hành v1.5 → G5 | G23: Data partnership, annotation, v1.5 release → G5 | H23: Kết quả gán nhãn thử (kappa) + v1.5 trên prod | I23: G5 | J23: PM, REG, DC, AI, SEC, QA, TW, OPS, QC | K23: Nhãn kém chất lượng; vướng thỏa thuận dữ liệu | L23: =SUMIFS('Daily Plan'!$N$4:$N$263,'Daily Plan'!$C$4:$C$263,A23) -> 40 | M23: =SUMIFS('Daily Plan'!$O$4:$O$263,'Daily Plan'!$C$4:$C$263,A23) -> 0 | N23: =COUNTIFS('Daily Plan'!$C$4:$C$263,A23,'Daily Plan'!$P$4:$P$263,"Xong") -> 0 | O23: =IFERROR(N23/COUNTIF('Daily Plan'!$C$4:$C$263,A23),0) -> 0
A24: S21 | B24: P6 · v2.0 — CT & giải phẫu cá nhân | C24: 41–42 | D24: =INDEX('Daily Plan'!$B$4:$B$263,MATCH(A24,'Daily Plan'!$C$4:$C$263,0)) -> 46605 | E24: =INDEX('Daily Plan'!$B$4:$B$263,MATCH(A24,'Daily Plan'!$C$4:$C$263,0)+9) -> 46618 | F24: Tái đánh giá pháp lý cho CT + tiếp nhận DICOM an toàn | G24: Regulatory re-assessment for CT + safe DICOM intake | H24: Upload series CT → DICOM đã khử định danh | I24: G0-R (CT) | J24: REG, IMG, SA, SEC, BE, DC, CSO, QA, QC | K24: Vượt ranh giới SaMD; PHI trong header/ảnh | L24: =SUMIFS('Daily Plan'!$N$4:$N$263,'Daily Plan'!$C$4:$C$263,A24) -> 40 | M24: =SUMIFS('Daily Plan'!$O$4:$O$263,'Daily Plan'!$C$4:$C$263,A24) -> 0 | N24: =COUNTIFS('Daily Plan'!$C$4:$C$263,A24,'Daily Plan'!$P$4:$P$263,"Xong") -> 0 | O24: =IFERROR(N24/COUNTIF('Daily Plan'!$C$4:$C$263,A24),0) -> 0
A25: S22 | B25: P6 · v2.0 — CT & giải phẫu cá nhân | C25: 43–44 | D25: =INDEX('Daily Plan'!$B$4:$B$263,MATCH(A25,'Daily Plan'!$C$4:$C$263,0)) -> 46619 | E25: =INDEX('Daily Plan'!$B$4:$B$263,MATCH(A25,'Daily Plan'!$C$4:$C$263,0)+9) -> 46636 | F25: Viewer lát cắt + segmentation + dựng mesh từ CT | G25: Slice viewer + segmentation + mesh from CT | H25: Xem lát cắt và mesh cơ quan dựng từ CT mẫu | I25: G1-D (lần 2) | J25: FE, IMG, MLO, QA, DC, AI, PM | K25: Chi phí GPU; mesh nặng | L25: =SUMIFS('Daily Plan'!$N$4:$N$263,'Daily Plan'!$C$4:$C$263,A25) -> 40 | M25: =SUMIFS('Daily Plan'!$O$4:$O$263,'Daily Plan'!$C$4:$C$263,A25) -> 0 | N25: =COUNTIFS('Daily Plan'!$C$4:$C$263,A25,'Daily Plan'!$P$4:$P$263,"Xong") -> 0 | O25: =IFERROR(N25/COUNTIF('Daily Plan'!$C$4:$C$263,A25),0) -> 0
A26: S23 | B26: P6 · v2.0 — CT & giải phẫu cá nhân | C26: 45–46 | D26: =INDEX('Daily Plan'!$B$4:$B$263,MATCH(A26,'Daily Plan'!$C$4:$C$263,0)) -> 46637 | E26: =INDEX('Daily Plan'!$B$4:$B$263,MATCH(A26,'Daily Plan'!$C$4:$C$263,0)+9) -> 46650 | F26: Căn chỉnh với template (registration) + liên kết báo cáo CT | G26: Template registration + linking CT reports | H26: So sánh template và giải phẫu cá nhân; finding đúng vị trí | J26: IMG, FE, BE, AI, CSO, UX, QA, PM | K26: Sai số căn chỉnh làm lệch vị trí | L26: =SUMIFS('Daily Plan'!$N$4:$N$263,'Daily Plan'!$C$4:$C$263,A26) -> 40 | M26: =SUMIFS('Daily Plan'!$O$4:$O$263,'Daily Plan'!$C$4:$C$263,A26) -> 0 | N26: =COUNTIFS('Daily Plan'!$C$4:$C$263,A26,'Daily Plan'!$P$4:$P$263,"Xong") -> 0 | O26: =IFERROR(N26/COUNTIF('Daily Plan'!$C$4:$C$263,A26),0) -> 0
A27: S24 | B27: P6 · v2.0 — CT & giải phẫu cá nhân | C27: 47–48 | D27: =INDEX('Daily Plan'!$B$4:$B$263,MATCH(A27,'Daily Plan'!$C$4:$C$263,0)) -> 46651 | E27: =INDEX('Daily Plan'!$B$4:$B$263,MATCH(A27,'Daily Plan'!$C$4:$C$263,0)+9) -> 46664 | F27: Distillation + tối ưu chi phí model | G27: Distillation + model cost optimisation | H27: Model nhỏ chạy shadow mode, so sánh chi phí/chất lượng | J27: MLO, AI, DE, SEC, REG, QA, PM | K27: Model nhỏ kém hơn ở ca khó | L27: =SUMIFS('Daily Plan'!$N$4:$N$263,'Daily Plan'!$C$4:$C$263,A27) -> 40 | M27: =SUMIFS('Daily Plan'!$O$4:$O$263,'Daily Plan'!$C$4:$C$263,A27) -> 0 | N27: =COUNTIFS('Daily Plan'!$C$4:$C$263,A27,'Daily Plan'!$P$4:$P$263,"Xong") -> 0 | O27: =IFERROR(N27/COUNTIF('Daily Plan'!$C$4:$C$263,A27),0) -> 0
A28: S25 | B28: P6 · v2.0 — CT & giải phẫu cá nhân | C28: 49–50 | D28: =INDEX('Daily Plan'!$B$4:$B$263,MATCH(A28,'Daily Plan'!$C$4:$C$263,0)) -> 46665 | E28: =INDEX('Daily Plan'!$B$4:$B$263,MATCH(A28,'Daily Plan'!$C$4:$C$263,0)+9) -> 46678 | F28: FHIR export, hardening v2, xác thực lâm sàng CT | G28: FHIR export, v2 hardening, CT clinical validation | H28: Xuất FHIR Bundle hợp lệ; báo cáo xác thực CT | J28: CIN, BE, SEC, CSO, QA, SRE, TW, SUP, QC, PM | K28: Thiếu thời gian hardening trước v2 | L28: =SUMIFS('Daily Plan'!$N$4:$N$263,'Daily Plan'!$C$4:$C$263,A28) -> 40 | M28: =SUMIFS('Daily Plan'!$O$4:$O$263,'Daily Plan'!$C$4:$C$263,A28) -> 0 | N28: =COUNTIFS('Daily Plan'!$C$4:$C$263,A28,'Daily Plan'!$P$4:$P$263,"Xong") -> 0 | O28: =IFERROR(N28/COUNTIF('Daily Plan'!$C$4:$C$263,A28),0) -> 0
A29: S26 | B29: P6 · v2.0 — CT & giải phẫu cá nhân | C29: 51–52 | D29: =INDEX('Daily Plan'!$B$4:$B$263,MATCH(A29,'Daily Plan'!$C$4:$C$263,0)) -> 46679 | E29: =INDEX('Daily Plan'!$B$4:$B$263,MATCH(A29,'Daily Plan'!$C$4:$C$263,0)+9) -> 46692 | F29: Phát hành v2.0 + đóng năm 1 → G6 | G29: Release v2.0 + year-1 closure → G6 | H29: v2.0 trên prod + closure report | I29: G6 | J29: PM, OPS, SRE, REG, TW, QC | K29: Không đóng dự án, thiếu bài học | L29: =SUMIFS('Daily Plan'!$N$4:$N$263,'Daily Plan'!$C$4:$C$263,A29) -> 40 | M29: =SUMIFS('Daily Plan'!$O$4:$O$263,'Daily Plan'!$C$4:$C$263,A29) -> 0 | N29: =COUNTIFS('Daily Plan'!$C$4:$C$263,A29,'Daily Plan'!$P$4:$P$263,"Xong") -> 0 | O29: =IFERROR(N29/COUNTIF('Daily Plan'!$C$4:$C$263,A29),0) -> 0

Sheet Daily Plan
A1: Kế hoạch theo ngày / Daily plan — 260 ngày làm việc
A2: Ô vàng = nhập (Giờ TT, Trạng thái, Ghi chú). Ngày tự tính từ Settings!C4 + Holidays. Cột Skill = skill agent cần gọi.
A3: Ngày # | B3: Ngày / Date | C3: Sprint | D3: Tuần KH | E3: Ngày trong sprint | F3: Phase | G3: Role | H3: Skill (agent) | I3: Việc (VI) | J3: Task (EN) | K3: Đầu ra / Deliverable | L3: Tiêu chí xong (DoD) | M3: Cổng / Gate | N3: Giờ KH | O3: Giờ TT | P3: Trạng thái | Q3: Cảnh báo | R3: Ghi chú
A4: 1 | B4: =WORKDAY(Settings!$C$4-1,A4,Holidays!$A$5:$A$40) -> 46314 | C4: S01 | D4: =INT((A4-1)/5)+1 -> 1 | E4: =MOD(A4-1,10)+1 -> 1 | F4: P0 · Khởi tạo & Discovery | G4: PM | H4: =IFERROR(INDEX(Roles!$D$5:$D$26,MATCH(G4,Roles!$A$5:$A$26,0)),"") -> medilens-product-manager | I4: Sprint Planning (1h); viết Project Charter 2 trang: mục tiêu, phạm vi, ngân sách, tiêu chí thành công | J4: Sprint Planning (1h); write a 2-page Project Charter: goals, scope, budget, success criteria | K4: docs/00-charter.md | L4: ≥ 3 mục tiêu đo được, ngân sách tháng, top-5 rủi ro | N4: =Settings!$C$5 -> 4 | P4: Chưa làm | Q4: =IF(OR(P4="Xong",P4="Bỏ"),"",IF(B4<TODAY(),"Quá hạn",IF(B4=TODAY(),"Hôm nay","")))
A5: 2 | B5: =WORKDAY(Settings!$C$4-1,A5,Holidays!$A$5:$A$40) -> 46315 | C5: S01 | D5: =INT((A5-1)/5)+1 -> 1 | E5: =MOD(A5-1,10)+1 -> 2 | F5: P0 · Khởi tạo & Discovery | G5: PM | H5: =IFERROR(INDEX(Roles!$D$5:$D$26,MATCH(G5,Roles!$A$5:$A$26,0)),"") -> medilens-product-manager | I5: Business case (có phương án 'không làm'); stakeholder register; quản trị: steering = bạn + mentor + bác sĩ cố vấn | J5: Business case incl. do-nothing option; stakeholder register; governance: steering = you + mentor + clinical advisor | K5: business-case.md, stakeholders.md | L5: Steering có tên người, lịch họp cuối mỗi phase, mẫu báo cáo tháng | N5: =Settings!$C$5 -> 4 | P5: Chưa làm | Q5: =IF(OR(P5="Xong",P5="Bỏ"),"",IF(B5<TODAY(),"Quá hạn",IF(B5=TODAY(),"Hôm nay","")))
A6: 3 | B6: =WORKDAY(Settings!$C$4-1,A6,Holidays!$A$5:$A$40) -> 46316 | C6: S01 | D6: =INT((A6-1)/5)+1 -> 1 | E6: =MOD(A6-1,10)+1 -> 3 | F6: P0 · Khởi tạo & Discovery | G6: REG | H6: =IFERROR(INDEX(Roles!$D$5:$D$26,MATCH(G6,Roles!$A$5:$A$26,0)),"") -> medilens-regulatory-privacy-officer | I6: Viết Intended Use Statement và danh sách ngoài phạm vi (không chẩn đoán, không gợi ý điều trị, không phát hiện bệnh trên ảnh) | J6: Write the Intended Use Statement and out-of-scope list (no diagnosis, no treatment advice, no image-based detection) | K6: regulatory/intended-use.md | L6: Không có động từ chẩn đoán; có danh sách từ cấm dùng trong claims | N6: =Settings!$C$5 -> 4 | P6: Chưa làm | Q6: =IF(OR(P6="Xong",P6="Bỏ"),"",IF(B6<TODAY(),"Quá hạn",IF(B6=TODAY(),"Hôm nay","")))
A7: 4 | B7: =WORKDAY(Settings!$C$4-1,A7,Holidays!$A$5:$A$40) -> 46317 | C7: S01 | D7: =INT((A7-1)/5)+1 -> 1 | E7: =MOD(A7-1,10)+1 -> 4 | F7: P0 · Khởi tạo & Discovery | G7: REG | H7: =IFERROR(INDEX(Roles!$D$5:$D$26,MATCH(G7,Roles!$A$5:$A$26,0)),"") -> medilens-regulatory-privacy-officer | I7: Regulatory Decision Record nháp: NĐ 98/2021 (sửa đổi 07/2023, 04/2025), TT 05/2022, Luật BVDLCN 91/2025/QH15, TT 13/2025/TT-BYT | J7: Draft Regulatory Decision Record: Decree 98/2021 (amended 07/2023, 04/2025), Circular 05/2022, PDPL 91/2025/QH15, Circular 13/2025/TT-BYT | K7: regulatory/RDR-001.md | L7: Mỗi kết luận có trích dẫn nguồn và ngày rà soát lại | N7: =Settings!$C$5 -> 4 | P7: Chưa làm | Q7: =IF(OR(P7="Xong",P7="Bỏ"),"",IF(B7<TODAY(),"Quá hạn",IF(B7=TODAY(),"Hôm nay","")))
A8: 5 | B8: =WORKDAY(Settings!$C$4-1,A8,Holidays!$A$5:$A$40) -> 46318 | C8: S01 | D8: =INT((A8-1)/5)+1 -> 1 | E8: =MOD(A8-1,10)+1 -> 5 | F8: P0 · Khởi tạo & Discovery | G8: BA | H8: =IFERROR(INDEX(Roles!$D$5:$D$26,MATCH(G8,Roles!$A$5:$A$26,0)),"") -> medilens-business-analyst | I8: Kế hoạch nghiên cứu người dùng: kịch bản phỏng vấn, mẫu đồng ý tham gia; tuyển 5–8 người (bệnh nhân, người nhà) | J8: User research plan: interview guide, consent form; recruit 5–8 patients/caregivers | K8: research/interview-guide.md | L8: Có mẫu consent; ≥ 5 buổi đã hẹn | N8: =Settings!$C$5 -> 4 | P8: Chưa làm | Q8: =IF(OR(P8="Xong",P8="Bỏ"),"",IF(B8<TODAY(),"Quá hạn",IF(B8=TODAY(),"Hôm nay","")))
A9: 6 | B9: =WORKDAY(Settings!$C$4-1,A9,Holidays!$A$5:$A$40) -> 46321 | C9: S01 | D9: =INT((A9-1)/5)+1 -> 2 | E9: =MOD(A9-1,10)+1 -> 6 | F9: P0 · Khởi tạo & Discovery | G9: BA | H9: =IFERROR(INDEX(Roles!$D$5:$D$26,MATCH(G9,Roles!$A$5:$A$26,0)),"") -> medilens-business-analyst | I9: Phỏng vấn 3 người; viết ghi chú ẩn danh ngay sau mỗi buổi | J9: Run 3 interviews; write anonymised notes right after each | K9: research/notes/ | L9: Ghi chú không chứa tên, SĐT, mã hồ sơ | N9: =Settings!$C$5 -> 4 | P9: Chưa làm | Q9: =IF(OR(P9="Xong",P9="Bỏ"),"",IF(B9<TODAY(),"Quá hạn",IF(B9=TODAY(),"Hôm nay","")))
A10: 7 | B10: =WORKDAY(Settings!$C$4-1,A10,Holidays!$A$5:$A$40) -> 46322 | C10: S01 | D10: =INT((A10-1)/5)+1 -> 2 | E10: =MOD(A10-1,10)+1 -> 7 | F10: P0 · Khởi tạo & Discovery | G10: UX | H10: =IFERROR(INDEX(Roles!$D$5:$D$26,MATCH(G10,Roles!$A$5:$A$26,0)),"") -> medilens-ux-ui-designer | I10: Phỏng vấn 2–3 người còn lại; affinity map các vấn đề | J10: Run the remaining 2–3 interviews; build an affinity map | K10: FigJam affinity map | L10: ≥ 5 cuộc phỏng vấn được gom thành chủ đề | N10: =Settings!$C$5 -> 4 | P10: Chưa làm | Q10: =IF(OR(P10="Xong",P10="Bỏ"),"",IF(B10<TODAY(),"Quá hạn",IF(B10=TODAY(),"Hôm nay","")))
A11: 8 | B11: =WORKDAY(Settings!$C$4-1,A11,Holidays!$A$5:$A$40) -> 46323 | C11: S01 | D11: =INT((A11-1)/5)+1 -> 2 | E11: =MOD(A11-1,10)+1 -> 8 | F11: P0 · Khởi tạo & Discovery | G11: UX | H11: =IFERROR(INDEX(Roles!$D$5:$D$26,MATCH(G11,Roles!$A$5:$A$26,0)),"") -> medilens-ux-ui-designer | I11: Persona (bệnh nhân, người chăm sóc, bác sĩ nhận chia sẻ) + user journey As-Is | J11: Personas (patient, caregiver, receiving clinician) + As-Is user journey | K11: personas, journey-asis | L11: Mỗi pain point dẫn chiếu bằng chứng phỏng vấn | N11: =Settings!$C$5 -> 4 | P11: Chưa làm | Q11: =IF(OR(P11="Xong",P11="Bỏ"),"",IF(B11<TODAY(),"Quá hạn",IF(B11=TODAY(),"Hôm nay","")))
A12: 9 | B12: =WORKDAY(Settings!$C$4-1,A12,Holidays!$A$5:$A$40) -> 46324 | C12: S01 | D12: =INT((A12-1)/5)+1 -> 2 | E12: =MOD(A12-1,10)+1 -> 9 | F12: P0 · Khởi tạo & Discovery | G12: CSO | H12: =IFERROR(INDEX(Roles!$D$5:$D$26,MATCH(G12,Roles!$A$5:$A$26,0)),"") -> medilens-clinical-safety-officer | I12: Tìm bác sĩ cố vấn (1–2 giờ/tháng); Clinical Risk Management Plan nháp + mẫu hazard log | J12: Recruit a clinical advisor (1–2 h/month); draft Clinical Risk Management Plan + hazard-log template | K12: safety/CRMP.md, hazard-log.xlsx | L12: Cố vấn đồng ý (hoặc có phương án dự phòng); hazard log theo ISO 14971 | N12: =Settings!$C$5 -> 4 | P12: Chưa làm | Q12: =IF(OR(P12="Xong",P12="Bỏ"),"",IF(B12<TODAY(),"Quá hạn",IF(B12=TODAY(),"Hôm nay","")))
A13: 10 | B13: =WORKDAY(Settings!$C$4-1,A13,Holidays!$A$5:$A$40) -> 46325 | C13: S01 | D13: =INT((A13-1)/5)+1 -> 2 | E13: =MOD(A13-1,10)+1 -> 10 | F13: P0 · Khởi tạo & Discovery | G13: PM | H13: =IFERROR(INDEX(Roles!$D$5:$D$26,MATCH(G13,Roles!$A$5:$A$26,0)),"") -> medilens-product-manager | I13: Sprint Review + Retro; cập nhật risk register; buffer cho việc trễ | J13: Sprint review + retro; update risk register; buffer for slipped work | K13: reports/sprint-01.md | L13: Retro có ≥ 1 hành động; rủi ro chấm điểm L×I | N13: =Settings!$C$5 -> 4 | P13: Chưa làm | Q13: =IF(OR(P13="Xong",P13="Bỏ"),"",IF(B13<TODAY(),"Quá hạn",IF(B13=TODAY(),"Hôm nay","")))
A14: 11 | B14: =WORKDAY(Settings!$C$4-1,A14,Holidays!$A$5:$A$40) -> 46328 | C14: S02 | D14: =INT((A14-1)/5)+1 -> 3 | E14: =MOD(A14-1,10)+1 -> 1 | F14: P0 · Khởi tạo & Discovery | G14: BA | H14: =IFERROR(INDEX(Roles!$D$5:$D$26,MATCH(G14,Roles!$A$5:$A$26,0)),"") -> medilens-business-analyst | I14: Planning; problem statement + MoSCoW; khóa MVP 3 Unit: Răng hàm mặt, Tim mạch, Ung bướu | J14: Planning; problem statement + MoSCoW; lock MVP to 3 Units: Dental, Cardiology, Oncology | K14: product/mvp-scope.md | L14: Must ≤ 3 Unit; danh sách Won't ghi rõ | N14: =Settings!$C$5 -> 4 | P14: Chưa làm | Q14: =IF(OR(P14="Xong",P14="Bỏ"),"",IF(B14<TODAY(),"Quá hạn",IF(B14=TODAY(),"Hôm nay","")))
A15: 12 | B15: =WORKDAY(Settings!$C$4-1,A15,Holidays!$A$5:$A$40) -> 46329 | C15: S02 | D15: =INT((A15-1)/5)+1 -> 3 | E15: =MOD(A15-1,10)+1 -> 2 | F15: P0 · Khởi tạo & Discovery | G15: BA | H15: =IFERROR(INDEX(Roles!$D$5:$D$26,MATCH(G15,Roles!$A$5:$A$26,0)),"") -> medilens-business-analyst | I15: BRD v1: quy trình To-Be (BPMN), business rules BR-001…BR-045, glossary VI–EN | J15: BRD v1: To-Be process (BPMN), business rules BR-001…BR-045, VI–EN glossary | K15: docs/BRD-v1.md | L15: Mỗi BR có mã, chủ sở hữu, ý tưởng test | N15: =Settings!$C$5 -> 4 | P15: Chưa làm | Q15: =IF(OR(P15="Xong",P15="Bỏ"),"",IF(B15<TODAY(),"Quá hạn",IF(B15=TODAY(),"Hôm nay","")))
... A22: 19 | B22: =WORKDAY(Settings!$C$4-1,A22,Holidays!$A$5:$A$40) -> 46338 | C22: S02 | D22: =INT((A22-1)/5)+1 -> 4 | E22: =MOD(A22-1,10)+1 -> 9 | F22: P0 · Khởi tạo & Discovery | G22: REG | H22: =IFERROR(INDEX(Roles!$D$5:$D$26,MATCH(G22,Roles!$A$5:$A$26,0)),"") -> medilens-regulatory-privacy-officer | I22: DPIA sơ bộ + kiểm kê dữ liệu; quyết định có cần hồ sơ đánh giá chuyển dữ liệu ra nước ngoài (OTIA) không | J22: Initial DPIA + data inventory; decide whether an outbound transfer impact assessment (OTIA) is needed | K22: privacy/DPIA-v0.md | L22: Mỗi loại dữ liệu có mục đích, cơ sở pháp lý, thời hạn lưu | N22: =Settings!$C$5 -> 4 | P22: Chưa làm | Q22: =IF(OR(P22="Xong",P22="Bỏ"),"",IF(B22<TODAY(),"Quá hạn",IF(B22=TODAY(),"Hôm nay","")))
A23: 20 | B23: =WORKDAY(Settings!$C$4-1,A23,Holidays!$A$5:$A$40) -> 46339 | C23: S02 | D23: =INT((A23-1)/5)+1 -> 4 | E23: =MOD(A23-1,10)+1 -> 10 | F23: P0 · Khởi tạo & Discovery | G23: QC | H23: =IFERROR(INDEX(Roles!$D$5:$D$26,MATCH(G23,Roles!$A$5:$A$26,0)),"") -> medilens-qc-release-gatekeeper | I23: Cổng G0 + G0-R: duyệt Brief, BRD, prototype, Intended Use, RDR; Review + Retro | J23: Gates G0 + G0-R: approve brief, BRD, prototype, intended use, RDR; review + retro | K23: gates/G0.md | L23: Biên bản cổng có người duyệt; không còn blocker | M23: G0, G0-R | N23: =Settings!$C$5 -> 4 | P23: Chưa làm | Q23: =IF(OR(P23="Xong",P23="Bỏ"),"",IF(B23<TODAY(),"Quá hạn",IF(B23=TODAY(),"Hôm nay","")))
A24: 21 | B24: =WORKDAY(Settings!$C$4-1,A24,Holidays!$A$5:$A$40) -> 46342 | C24: S03 | D24: =INT((A24-1)/5)+1 -> 5 | E24: =MOD(A24-1,10)+1 -> 1 | F24: P1 · Foundation | G24: SA | H24: =IFERROR(INDEX(Roles!$D$5:$D$26,MATCH(G24,Roles!$A$5:$A$26,0)),"") -> medilens-solution-architect | I24: Planning; sơ đồ C4 (context, container) + khung SAD arc42 | J24: Planning; C4 context/container diagrams + arc42 SAD skeleton | K24: docs/SAD.md | L24: Sơ đồ có trust boundary và luồng PHI | N24: =Settings!$C$5 -> 4 | P24: Chưa làm | Q24: =IF(OR(P24="Xong",P24="Bỏ"),"",IF(B24<TODAY(),"Quá hạn",IF(B24=TODAY(),"Hôm nay","")))
A25: 22 | B25: =WORKDAY(Settings!$C$4-1,A25,Holidays!$A$5:$A$40) -> 46343 | C25: S03 | D25: =INT((A25-1)/5)+1 -> 5 | E25: =MOD(A25-1,10)+1 -> 2 | F25: P1 · Foundation | G25: OPS | H25: =IFERROR(INDEX(Roles!$D$5:$D$26,MATCH(G25,Roles!$A$5:$A$26,0)),"") -> medilens-cloud-devops-engineer | I25: Monorepo (apps/web, apps/api, apps/worker, infra); pre-commit: lint, format, quét secrets | J25: Monorepo (apps/web, apps/api, apps/worker, infra); pre-commit: lint, format, secret scan | K25: repo | L25: Hook chạy được; README hướng dẫn chạy local | N25: =Settings!$C$5 -> 4 | P25: Chưa làm | Q25: =IF(OR(P25="Xong",P25="Bỏ"),"",IF(B25<TODAY(),"Quá hạn",IF(B25=TODAY(),"Hôm nay","")))
A26: 23 | B26: =WORKDAY(Settings!$C$4-1,A26,Holidays!$A$5:$A$40) -> 46344 | C26: S03 | D26: =INT((A26-1)/5)+1 -> 5 | E26: =MOD(A26-1,10)+1 -> 3 | F26: P1 · Foundation | G26: OPS | H26: =IFERROR(INDEX(Roles!$D$5:$D$26,MATCH(G26,Roles!$A$5:$A$26,0)),"") -> medilens-cloud-devops-engineer | I26: GitHub Actions CI: lint, unit test, SAST (Semgrep), SCA, build image, SBOM | J26: GitHub Actions CI: lint, unit tests, SAST (Semgrep), SCA, image build, SBOM | K26: .github/workflows/ci.yml | L26: CI xanh trên main; chặn High/Critical | N26: =Settings!$C$5 -> 4 | P26: Chưa làm | Q26: =IF(OR(P26="Xong",P26="Bỏ"),"",IF(B26<TODAY(),"Quá hạn",IF(B26=TODAY(),"Hôm nay","")))
A27: 24 | B27: =WORKDAY(Settings!$C$4-1,A27,Holidays!$A$5:$A$40) -> 46345 | C27: S03 | D27: =INT((A27-1)/5)+1 -> 5 | E27: =MOD(A27-1,10)+1 -> 4 | F27: P1 · Foundation | G27: OPS | H27: =IFERROR(INDEX(Roles!$D$5:$D$26,MATCH(G27,Roles!$A$5:$A$26,0)),"") -> medilens-cloud-devops-engineer | I27: AWS Organizations: account management, security, log-archive, nonprod, prod; IAM Identity Center; SCP cơ bản; CloudTrail org trail | J27: AWS Organizations: management, security, log-archive, nonprod, prod accounts; Identity Center; baseline SCPs; org CloudTrail | K27: infra/org | L27: Root có MFA phần cứng; không có IAM user dùng hằng ngày | N27: =Settings!$C$5 -> 4 | P27: Chưa làm | Q27: =IF(OR(P27="Xong",P27="Bỏ"),"",IF(B27<TODAY(),"Quá hạn",IF(B27=TODAY(),"Hôm nay","")))
A28: 25 | B28: =WORKDAY(Settings!$C$4-1,A28,Holidays!$A$5:$A$40) -> 46346 | C28: S03 | D28: =INT((A28-1)/5)+1 -> 5 | E28: =MOD(A28-1,10)+1 -> 5 | F28: P1 · Foundation | G28: OPS | H28: =IFERROR(INDEX(Roles!$D$5:$D$26,MATCH(G28,Roles!$A$5:$A$26,0)),"") -> medilens-cloud-devops-engineer | I28: Terraform VPC nonprod: subnet public/private/worker (worker không route internet), VPC endpoint S3/SQS/KMS/ECR/Logs/Bedrock | J28: Terraform nonprod VPC: public/private/worker subnets (worker with no internet route), VPC endpoints S3/SQS/KMS/ECR/Logs/Bedrock | K28: infra/network | L28: checkov/tfsec không có High; SEC-AR-03 có test | N28: =Settings!$C$5 -> 4 | P28: Chưa làm | Q28: =IF(OR(P28="Xong",P28="Bỏ"),"",IF(B28<TODAY(),"Quá hạn",IF(B28=TODAY(),"Hôm nay","")))
A29: 26 | B29: =WORKDAY(Settings!$C$4-1,A29,Holidays!$A$5:$A$40) -> 46349 | C29: S03 | D29: =INT((A29-1)/5)+1 -> 6 | E29: =MOD(A29-1,10)+1 -> 6 | F29: P1 · Foundation | G29: BE | H29: =IFERROR(INDEX(Roles!$D$5:$D$26,MATCH(G29,Roles!$A$5:$A$26,0)),"") -> medilens-backend-engineer | I29: Khung FastAPI: health check, lỗi dạng Problem Details, OpenAPI, cấu hình theo môi trường | J29: FastAPI skeleton: health check, Problem Details errors, OpenAPI, per-environment config | K29: apps/api | L29: /health trả 200; lỗi không lộ stack trace | N29: =Settings!$C$5 -> 4 | P29: Chưa làm | Q29: =IF(OR(P29="Xong",P29="Bỏ"),"",IF(B29<TODAY(),"Quá hạn",IF(B29=TODAY(),"Hôm nay","")))
A30: 27 | B30: =WORKDAY(Settings!$C$4-1,A30,Holidays!$A$5:$A$40) -> 46351 | C30: S03 | D30: =INT((A30-1)/5)+1 -> 6 | E30: =MOD(A30-1,10)+1 -> 7 | F30: P1 · Foundation | G30: BE | H30: =IFERROR(INDEX(Roles!$D$5:$D$26,MATCH(G30,Roles!$A$5:$A$26,0)),"") -> medilens-backend-engineer | I30: Cognito + OIDC Authorization Code/PKCE, kiểm JWT, cookie HttpOnly/Secure/SameSite | J30: Cognito + OIDC authorization code/PKCE, JWT validation, HttpOnly/Secure/SameSite cookies | K30: auth module | L30: E2E đăng nhập qua; không có token trong localStorage | N30: =Settings!$C$5 -> 4 | P30: Chưa làm | Q30: =IF(OR(P30="Xong",P30="Bỏ"),"",IF(B30<TODAY(),"Quá hạn",IF(B30=TODAY(),"Hôm nay","")))
A31: 28 | B31: =WORKDAY(Settings!$C$4-1,A31,Holidays!$A$5:$A$40) -> 46352 | C31: S03 | D31: =INT((A31-1)/5)+1 -> 6 | E31: =MOD(A31-1,10)+1 -> 8 | F31: P1 · Foundation | G31: FE | H31: =IFERROR(INDEX(Roles!$D$5:$D$26,MATCH(G31,Roles!$A$5:$A$26,0)),"") -> medilens-frontend-engineer | I31: Khung Next.js: layout, next-intl VI/EN, luồng đăng nhập/đăng xuất | J31: Next.js skeleton: layout, next-intl VI/EN, sign-in/sign-out flow | K31: apps/web | L31: Đủ key VI/EN; Lighthouse a11y ≥ 90 | N31: =Settings!$C$5 -> 4 | P31: Chưa làm | Q31: =IF(OR(P31="Xong",P31="Bỏ"),"",IF(B31<TODAY(),"Quá hạn",IF(B31=TODAY(),"Hôm nay","")))
A32: 29 | B32: =WORKDAY(Settings!$C$4-1,A32,Holidays!$A$5:$A$40) -> 46353 | C32: S03 | D32: =INT((A32-1)/5)+1 -> 6 | E32: =MOD(A32-1,10)+1 -> 9 | F32: P1 · Foundation | G32: SEC | H32: =IFERROR(INDEX(Roles!$D$5:$D$26,MATCH(G32,Roles!$A$5:$A$26,0)),"") -> medilens-security-engineer | I32: Threat model STRIDE v1 cho upload, AI, chia sẻ + abuse cases | J32: STRIDE threat model v1 for upload, AI and sharing + abuse cases | K32: security/threat-model.md | L32: Mỗi mối đe dọa có biện pháp và chủ sở hữu | N32: =Settings!$C$5 -> 4 | P32: Chưa làm | Q32: =IF(OR(P32="Xong",P32="Bỏ"),"",IF(B32<TODAY(),"Quá hạn",IF(B32=TODAY(),"Hôm nay","")))
A33: 30 | B33: =WORKDAY(Settings!$C$4-1,A33,Holidays!$A$5:$A$40) -> 46356 | C33: S03 | D33: =INT((A33-1)/5)+1 -> 6 | E33: =MOD(A33-1,10)+1 -> 10 | F33: P1 · Foundation | G33: PM | H33: =IFERROR(INDEX(Roles!$D$5:$D$26,MATCH(G33,Roles!$A$5:$A$26,0)),"") -> medilens-product-manager | I33: Review (video demo ≤ 5 phút) + Retro; buffer | J33: Review (≤ 5-min demo video) + retro; buffer | K33: reports/sprint-03.md | L33: Demo đăng nhập trên nonprod | N33: =Settings!$C$5 -> 4 | P33: Chưa làm | Q33: =IF(OR(P33="Xong",P33="Bỏ"),"",IF(B33<TODAY(),"Quá hạn",IF(B33=TODAY(),"Hôm nay","")))
A34: 31 | B34: =WORKDAY(Settings!$C$4-1,A34,Holidays!$A$5:$A$40) -> 46357 | C34: S04 | D34: =INT((A34-1)/5)+1 -> 7 | E34: =MOD(A34-1,10)+1 -> 1 | F34: P1 · Foundation | G34: BE | H34: =IFERROR(INDEX(Roles!$D$5:$D$26,MATCH(G34,Roles!$A$5:$A$26,0)),"") -> medilens-backend-engineer | I34: Planning; ERD theo domain model (User, PatientProfile, MedicalDocument, Finding, Unit/Region, Consent, AuditEvent) | J34: Planning; ERD from the domain model (User, PatientProfile, MedicalDocument, Finding, Unit/Region, Consent, AuditEvent) | K34: docs/erd | L34: Tên thực thể gần FHIR; review bằng checklist bảo mật | N34: =Settings!$C$5 -> 4 | P34: Chưa làm | Q34: =IF(OR(P34="Xong",P34="Bỏ"),"",IF(B34<TODAY(),"Quá hạn",IF(B34=TODAY(),"Hôm nay","")))
A35: 32 | B35: =WORKDAY(Settings!$C$4-1,A35,Holidays!$A$5:$A$40) -> 46358 | C35: S04 | D35: =INT((A35-1)/5)+1 -> 7 | E35: =MOD(A35-1,10)+1 -> 2 | F35: P1 · Foundation | G35: BE | H35: =IFERROR(INDEX(Roles!$D$5:$D$26,MATCH(G35,Roles!$A$5:$A$26,0)),"") -> medilens-backend-engineer | I35: PostgreSQL 16 + Alembic; schema identity và clinical tách riêng, role DB riêng | J35: PostgreSQL 16 + Alembic; separate identity and clinical schemas and DB roles | K35: migrations/ | L35: Migration up/down chạy trong CI | N35: =Settings!$C$5 -> 4 | P35: Chưa làm | Q35: =IF(OR(P35="Xong",P35="Bỏ"),"",IF(B35<TODAY(),"Quá hạn",IF(B35=TODAY(),"Hôm nay","")))
... A51: 48 | B51: =WORKDAY(Settings!$C$4-1,A51,Holidays!$A$5:$A$40) -> 46380 | C51: S05 | D51: =INT((A51-1)/5)+1 -> 10 | E51: =MOD(A51-1,10)+1 -> 8 | F51: P1 · Foundation | G51: CIN | H51: =IFERROR(INDEX(Roles!$D$5:$D$26,MATCH(G51,Roles!$A$5:$A$26,0)),"") -> medilens-clinical-informaticist | I51: Nạp danh mục mã: ICD-10 (bản Bộ Y tế), tập con LOINC, FDI; ghi license vào register | J51: Load code systems: MoH ICD-10, LOINC subset, FDI; record licences in the register | K51: terminology tables | L51: Loader có test; license đã ghi | N51: =Settings!$C$5 -> 4 | P51: Chưa làm | Q51: =IF(OR(P51="Xong",P51="Bỏ"),"",IF(B51<TODAY(),"Quá hạn",IF(B51=TODAY(),"Hôm nay","")))
A52: 49 | B52: =WORKDAY(Settings!$C$4-1,A52,Holidays!$A$5:$A$40) -> 46381 | C52: S05 | D52: =INT((A52-1)/5)+1 -> 10 | E52: =MOD(A52-1,10)+1 -> 9 | F52: P1 · Foundation | G52: DC | H52: =IFERROR(INDEX(Roles!$D$5:$D$26,MATCH(G52,Roles!$A$5:$A$26,0)),"") -> medilens-data-curator | I52: G1-D lần 1 cho dữ liệu đánh giá & synthetic: Dataset Card, checksum, kiểm trùng hash giữa các tập | J52: G1-D round 1 for evaluation & synthetic data: Dataset Card, checksum, hash-based leakage check | K52: datasets/cards | L52: Checklist 25.6 đạt cho dữ liệu đánh giá | M52: G1-D | N52: =Settings!$C$5 -> 4 | P52: Chưa làm | Q52: =IF(OR(P52="Xong",P52="Bỏ"),"",IF(B52<TODAY(),"Quá hạn",IF(B52=TODAY(),"Hôm nay","")))
